Workbook

Sheet balance
C1: 2024.12.31 | D1: 2023.12.31 | E1: 2022.12.31 | F1: 2021.12.31 | G1: 2020.12.31 | H1: 2019.12.31 | I1: 2018.12.21 | J1: 2017.12.31 | K1: 2016.12.31 | L1: 2015.12.31
A2: 资产 | C2: =C4+C13+C25+C10 -> 63254182536 | D2: =D4+D13+D25+D10 -> 56630407495 | E2: =E4+E13+E25+E10 -> 50767498791 | F2: =F4+F13+F25+F10 -> 44784893954 | G2: =G4+G13+G25+G10 -> 38423625184 | H2: =H4+H13+H25+H10 -> 38826279607 | I2: =I4+I13+I25+I10 -> 34490438670 | J2: =J4+J13+J25+J10 -> 31920898046 | ... L2: =L4+L13+L25+L10 -> 24640919497
A4: 金融资产 | C4: =SUM(C5:C9) -> 20713712160 | D4: =SUM(D5:D9) -> 19838830944 | E4: =SUM(E5:E9) -> 18165180172 | F4: =SUM(F5:F9) -> 15447688808 | G4: =SUM(G5:G9) -> 10411885641 | H4: =SUM(H5:H9) -> 10001551003 | I4: =SUM(I5:I9) -> 6800777265 | J4: =SUM(J5:J9) -> 6833689446 | ... L4: =SUM(L5:L9) -> 5918845168
B5: 货币资金 | C5: 18784564004 | D5: 18518172689 | E5: 17019655848 | F5: 14327356262 | G5: 8809985853 | H5: 8356153735 | I5: 6365973126 | J5: 6728200042 | K5: 7211178987 | L5: 5918845168
B6: 交易性金融资产（权益工具、存款） | C6: 7682574 | D6: 5740618 | E6: 7396158 | F6: 6320181 | G6: 300287671 | H6: 860894383 | I6: 387261777 | J6: 101927854 | K6: 1951267
B7: 衍生金融资产 | H7: 85110 | I7: 47542362 | J7: 3561550
B8: 应收款项融资 | C8: 1921465582 | D8: 1314917637 | E8: 1138128166 | F8: 1114012365 | G8: 1301612117 | H8: 784417775
B9: 其他流动资产
A10: 长期股权资产 | C10: =SUM(C11:C12) -> 524177494 | D10: =SUM(D11:D12) -> 272592774 | E10: =SUM(E11:E12) -> 327607056 | F10: =SUM(F11:F12) -> 298144705 | G10: =SUM(G11:G12) -> 264748905 | H10: =SUM(H11:H12) -> 199805151 | I10: =SUM(I11:I12) -> 205738050 | J10: =SUM(J11:J12) -> 95519959 | ... L10: =SUM(L11:L12) -> 46449341
B11: 长期股权投资 | C11: 441494759 | D11: 181538429 | E11: 250040313 | F11: 228823950 | G11: 206748905 | H11: 199805151 | I11: 205738050 | J11: 95519959 | K11: 101536425 | L11: 46449341
B12: 其他权益工具投资 | C12: 82682735 | D12: 91054345 | E12: 77566743 | F12: 69320755 | G12: 58000000
A13: 经营资产 | C13: =SUM(C14:C24) -> 16094542311 | D13: =SUM(D14:D24) -> 14147469320 | E13: =SUM(E14:E24) -> 12235113740 | F13: =SUM(F14:F24) -> 10129858419 | G13: =SUM(G14:G24) -> 8668361952 | H13: =SUM(H14:H24) -> 8471317618 | I13: =SUM(I14:I24) -> 9033666442 | J13: =SUM(J14:J24) -> 8680763546 | ... L13: =SUM(L14:L24) -> 6631629264
B14: 存货 | C14: 5970614068 | D14: 5143615319 | E14: 5403360356 | F14: 4327048485 | G14: 3280989599 | H14: 3280465303 | I14: 3241739977 | J14: 2974677451 | K14: 2785865099 | L14: =2494920809+320467619 -> 2815388428
B15: 应收票据 | C15: 812397864 | D15: 367992386 | E15: 204452983 | F15: 38888270 | G15: 19430381 | H15: 20011631 | I15: 710399926 | J15: 921383461 | K15: 871597857 | L15: 569748367
B16: 应收账款 | C16: 8157067130 | D16: 7128016386 | E16: 5257513588 | F16: 4311233501 | G16: 3734495117 | H16: 3457428686 | I16: 3593707590 | J16: 3716260518 | K16: 3636343106 | L16: 2762405078
B17: 预付款项 | C17: 305455256 | D17: 316529520 | E17: 235934604 | F17: 238959820 | G17: 173525313 | H17: 222501827 | I17: 220126772 | J17: 195521295 | K17: 150956724 | L17: 178812459
B18: 其他应收款 | C18: 126106574 | D18: 143819252 | E18: 138098796 | F18: 160746854 | G18: 526506578 | H18: 472000751 | I18: 510753825 | J18: 105412820 | K18: 118430342 | L18: 86561210
B19: 其他流动资产 | C19: 317730736 | D19: 281151242 | E19: 273366871 | F19: 158536366 | G19: 252804600 | H19: 320404434 | I19: 313634314 | J19: 259548554 | K19: 174699089
B20: 其他非流动资产 | I20: 842960 | J20: 1210710 | K20: 289450
B21: 一年到期流动资产 | D21: 316416243 | I21: 190000000
B22: 一年内到期非流动资产 | G22: 160000000 | K22: 16936288 | L22: 14065004
B23: 长期应收款 | C23: 30104757 | D23: 28891321 | E23: 316416243 | F23: 461516243 | H23: 180000000 | J23: 190000000
B24: 递延所得税资产 | C24: 375065926 | D24: 421037651 | E24: 405970299 | F24: 432928880 | G24: 520610364 | H24: 518504986 | I24: 252461078 | J24: 316748737 | K24: 193403942 | L24: 204648718
A25: 长期资产 | C25: =SUM(C26:C31) -> 25921750571 | D25: =SUM(D26:D31) -> 22371514457 | E25: =SUM(E26:E31) -> 20039597823 | F25: =SUM(F26:F31) -> 18909202022 | G25: =SUM(G26:G31) -> 19078628686 | H25: =SUM(H26:H31) -> 20153605835 | I25: =SUM(I26:I31) -> 18450256913 | J25: =SUM(J26:J31) -> 16310925095 | ... L25: =SUM(L26:L31) -> 12043995724
B26: 固定资产 | C26: 16449536181 | D26: 14955242773 | E26: 14445878801 | F26: 14501764063 | G26: 14260438910 | H26: 14520366436 | I26: 13629887296 | J26: 11332521554 | K26: 9267464872 | L26: 7688519842
B27: 在建工程 | C27: 6509671375 | D27: 4766144830 | E27: 3133499992 | F27: 1976816816 | G27: 2354298463 | H27: 2901032823 | I27: 2936812592 | J27: 3366783284 | K27: 3821964355 | L27: 2842566308
B28: 使用权资产 | C28: 532127082 | D28: 628448631 | E28: 575442101 | F28: 595392579 | G28: 607068550 | H28: 701329178
B29: 无形资产 | C29: 1600767546 | D29: 1315862480 | E29: 1245410813 | F29: 1235091876 | G29: 1270843245 | H29: 1337282523 | I29: 1219578721 | J29: 1098130404 | K29: 1148077027 | L29: 1179236213
B30: 商誉 | C30: 153707174 | D30: 154940513 | E30: 154940513 | F30: 154940513 | G30: 154940513 | H30: 154940513 | I30: 153707174 | J30: 74678326 | K30: 74678326 | L30: 74678326
B31: 长期待摊 | C31: 675941213 | D31: 550875230 | E31: 484425603 | F31: 445196175 | G31: 431039005 | H31: 538654362 | I31: 510271130 | J31: 438811527 | K31: 290472267 | L31: 258995035
A33: 负债 | C33: =C35+C49 -> 27568613358 | D33: =D35+D49 -> 25219085168 | E33: =E35+E49 -> 21779200663 | F33: =F35+F49 -> 18490789663 | G33: =G35+G49 -> 16832717886 | H33: =H35+H49 -> 17457198085 | I33: =I35+I49 -> 14300566064 | J33: =J35+J49 -> 13123026239 | ... L33: =L35+L49 -> 8411904960
A35: 经营负债 | C35: =SUM(C36:C48) -> 12573314784 | D35: =SUM(D36:D48) -> 10683161206 | E35: =SUM(E36:E48) -> 8767191100 | F35: =SUM(F36:F48) -> 7285142620 | G35: =SUM(G36:G48) -> 6398132763 | H35: =SUM(H36:H48) -> 6073728547 | I35: =SUM(I36:I48) -> 5897287132 | J35: =SUM(J36:J48) -> 5202569264 | ... L35: =SUM(L36:L48) -> 3669285297
B36: 应付票据 | C36: 3007490592 | D36: 2825386573 | E36: 2128399828 | F36: 1623267716 | G36: 1166210433 | H36: 860739543 | K36: 613982362 | L36: 460160232
B37: 应付账款 | C37: 2795604397 | D37: 2697600166 | E37: 2025309794 | F37: 1524955089 | G37: 1299794957 | H37: 1236580062 | I37: 2465349981 | J37: 2401097118 | K37: 1300220344 | L37: 909111745
B38: 预收款项 | K38: 21435585 | L38: 33985494
B39: 合同负债 | C39: 807312590 | D39: 979067305 | E39: 931585408 | F39: 863737090 | G39: 756282114 | H39: 695400166 | I39: 594503112 | J39: 442282880
B40: 应付职工薪酬 | C40: 972229163 | D40: 816372688 | E40: 660389674 | F40: 530495062 | G40: 489357281 | H40: 473972041 | I40: 483015711 | J40: 439505286 | K40: 420291759 | L40: 353759783
B41: 应交税费 | C41: 600754415 | D41: 546430527 | E41: 404719169 | F41: 319532528 | G41: 302321505 | H41: 344357096 | I41: 449716675 | J41: 313192643 | K41: 558062870 | L41: 335339211
B42: 其他应付款 | C42: 2226134441 | D42: 1622250140 | E42: 1681942320 | F42: 1496548775 | G42: 1376997551 | H42: 1555660964 | I42: 1208118598 | J42: 1069106178 | K42: 1090612474 | L42: =1087807096+9551912 -> 1097359008
B43: 其他流动负债 | C43: 140768878
...

Sheet 损益现金流
B1: 2024 | C1: 2023 | D1: 2022 | E1: 2021 | F1: 2020 | G1: 2019 | H1: 2018 | I1: 2017 | J1: 2016 | K1: 2015
A2: 营收 | B2: 39251657267 | C2: 33160996641 | D2: 28098754166 | E2: 23603063361 | F2: 19906593468 | G2: 21103877523 | H2: 20224985720 | I2: 18713034974 | J2: 16621336273 | K2: 13573495055
A3: 成本 | B3: 25030877441 | C3: 21424326140 | D3: 18535445134 | E3: 15129053236 | F3: 12042217543 | G3: 13197554393 | H3: 11603054947 | I3: 10712611816 | J3: 9463313931 | K3: 7814343237
A4: 毛利率 | B4: =1-B3/B2 -> 0.36229756 | C4: =1-C3/C2 -> 0.35392997 | D4: =1-D3/D2 -> 0.34034637 | E4: =1-E3/E2 -> 0.35902162 | F4: =1-F3/F2 -> 0.39506387 | G4: =1-G3/G2 -> 0.37463841 | H4: =1-H3/H2 -> 0.42630096 | I4: =1-I3/I2 -> 0.4275321 | ... K4: =1-K3/K2 -> 0.42429395
A5: 税金及附加 | B5: 285987048 | C5: 239896621 | D5: 225341476 | E5: 204629142 | F5: 198182840 | G5: 197816747 | H5: 203072222 | I5: 200263617 | J5: 174265074 | K5: 112453855
A6: 销售费用 | B6: 1180260909 | C6: 1538783486 | D6: 1350721298 | E6: 1150992397 | F6: 1474366072 | G6: 1481567161 | H6: 1467671276 | I6: 1274308845 | J6: 1184740033 | K6: 1020584621
A7: 管理费用 | B7: 2888289768 | C7: 2486049334 | D7: 2142932036 | E7: 1944179027 | F7: 2076624937 | G7: 2185363063 | H7: 2063072209 | I7: 1797379424 | J7: 2392097806 | K7: 1873364984
A8: 研发费用 | B8: 1677751298 | C8: 1403030121 | D8: 1248592812 | E8: 997203019 | F8: 815579258 | G8: 813129835 | H8: 887721987 | I8: 803441192
A10: 其他收益 | B10: 400415185 | C10: 262917177 | D10: 215071387 | E10: 242337506 | F10: 352820556 | G10: 181754102 | H10: 146750220 | I10: 190690589
A11: 信用减值 | B11: -3562889 | C11: -17109861 | D11: -4092781 | E11: -5436372 | F11: -5986645 | G11: -20511657 | H11: -28131575
A12: 资产减值 | B12: =-108088278 -> -108088278 | C12: -205314035 | D12: -140304975 | E12: -18976018 | F12: -30973964 | G12: -3939955 | H12: -22335530 | I12: -5110700 | J12: -11224597 | K12: -11540935
A13: 资产处置 | B13: 13102488 | C13: 1647225 | D13: -6083766 | E13: 484341 | F13: 75117728 | G13: 4347754 | H13: -1279203 | I13: -26217990
A15: 营业外收入 | B15: 35905331 | C15: 49843149 | D15: 80855034 | E15: 217974835 | F15: 57628048 | G15: 109494454 | H15: 60687441 | I15: 27172108 | J15: 115204091 | K15: 129935252
A16: 营业外成本 | B16: 120136061 | C16: 125106357 | D16: 163122132 | E16: 161162665 | F16: 214664627 | G16: 294294341 | H16: 71545321 | I16: 17376997 | J16: 35438675 | K16: 138450464
A18: 息税前经营利润 | B18: =B2-B3-SUM(B5:B8)+SUM(B10:B13)+B15-B16 -> 8406126579 | C18: =C2-C3-SUM(C5:C8)+SUM(C10:C13)+C15-C16 -> 6035788237 | D18: =D2-D3-SUM(D5:D8)+SUM(D10:D13)+D15-D16 -> 4578044177 | E18: =E2-E3-SUM(E5:E8)+SUM(E10:E13)+E15-E16 -> 4452228167 | F18: =F2-F3-SUM(F5:F8)+SUM(F10:F13)+F15-F16 -> 3533563914 | G18: =G2-G3-SUM(G5:G8)+SUM(G10:G13)+G15-G16 -> 3205296681 | H18: =H2-H3-SUM(H5:H8)+SUM(H10:H13)+H15-H16 -> 4084539111 | I18: =I2-I3-SUM(I5:I8)+SUM(I10:I13)+I15-I16 -> 4094187090 | ... K18: =K2-K3-SUM(K5:K8)+SUM(K10:K13)+K15-K16 -> 2732692211
A20: 金融资产收益 | B20: =SUM(B21:B23) -> 924966003 | C20: =SUM(C21:C23) -> 602544066 | D20: =SUM(D21:D23) -> 231495735 | E20: =SUM(E21:E23) -> 195413923 | F20: =SUM(F21:F23) -> 348762592 | G20: =SUM(G21:G23) -> 336984661 | H20: =SUM(H21:H23) -> 335452093 | I20: =SUM(I21:I23) -> 137540567 | ... K20: =SUM(K21:K23) -> 16915996
A21: 投资收益 | B21: =-11293376+-44874617 -> -56167993 | C21: -9802782 | D21: =-16364000+-12840733 -> -29204733 | E21: =5235616+45414980+-14677491 -> 35973105 | F21: =68910527+-9922937+165722 -> 59153312 | G21: =98833082-10431971-90255 -> 88310856 | H21: =35253973+270490 -> 35524463
A22: 利息收入 | B22: 979192040 | C22: 614002388 | D22: 262733645 | E22: 168837719 | F22: 290289764 | G22: 284421399 | H22: 236034167 | I22: 156658899 | J22: 106577485 | K22: 19724867
A23: 公允价值变动 | B23: 1941956 | C23: =-1655540 -> -1655540 | D23: -2033177 | E23: -9396901 | F23: -680484 | G23: -35747594 | H23: 63893463 | I23: -19118332 | J23: 2776702 | K23: -2808871
A25: 长期投资收益 | B25: =SUM(B26:B28) -> -15801862 | C25: =SUM(C26:C28) -> 4290148 | D25: =SUM(D26:D28) -> 20962737 | E25: =SUM(E26:E28) -> 26975045 | F25: =SUM(F26:F28) -> 11843754 | G25: =SUM(G26:G28) -> -5932899 | H25: =SUM(H26:H28) -> 667776495 | I25: =SUM(I26:I28) -> 23390958 | ... K25: =SUM(K26:K28) -> 23781843
A26: 长期股权投资收益 | B26: =-15801862 -> -15801862 | C26: =10797721+-6507573 -> 4290148 | D26: 20962737 | E26: 26975045 | F26: 11843754 | G26: -5932899 | H26: =3743957+664032538 -> 667776495 | I26: =-6016466+29407424 -> 23390958 | J26: 41956332 | K26: 23781843
A27: 其他权益工具投资
A28: 公允价值变动
A30: 息税前净利润 | B30: =B18+B20+B25 -> 9315290720 | C30: =C18+C20+C25 -> 6642622451 | D30: =D18+D20+D25 -> 4830502649 | E30: =E18+E20+E25 -> 4674617135 | F30: =F18+F20+F25 -> 3894170260 | G30: =G18+G20+G25 -> 3536348443 | H30: =H18+H20+H25 -> 5087767699 | I30: =I18+I20+I25 -> 4255118615 | ... K30: =K18+K20+K25 -> 2773390050
A31: 利息支出 | B31: 288507082 | C31: 288319603 | D31: =284355835+14674435+-10908011 -> 288122259 | E31: =312535638+12662034-6256881 -> 318940791 | F31: =353836981+13932104-13016682 -> 354752403 | G31: =447223558+13912513-28456551 -> 432679520 | H31: =376230473 -> 376230473 | I31: =182373020 -> 182373020 | J31: =157713120 -> 157713120 | K31: =190512029 -> 190512029
A32: 财务费用 | B32: =24284937+11679111 -> 35964048 | C32: =-368696286+6977220 -> -361719066 | D32: =-1045237867+8512570 -> -1036725297 | E32: =528006272+8827978 -> 536834250 | F32: =422467723+7355091 -> 429822814 | G32: =-135763953+8294824 -> -127469129 | H32: =+-258516410+7693358 -> -250823052 | I32: =387506549+5517279 -> 393023828 | J32: =+-458716176+8148119 -> -450568057 | K32: =+-466734319+6887612 -> -459846707
A33: 所得税 | B33: 1486781220 | C33: 1086913641 | D33: 826310042 | E33: 675861301 | F33: 511144107 | G33: 332955880 | H33: 855187629 | I33: 531479253 | J33: 776909142 | K33: 435226131
A35: 净利润 | B35: =B30-B32-B33-B31 -> 7504038370 | C35: =C30-C32-C33-C31 -> 5629108273 | D35: =D30-D32-D33-D31 -> 4752795645 | E35: =E30-E32-E33-E31 -> 3142980793 | F35: =F30-F32-F33-F31 -> 2598450936 | G35: =G30-G32-G33-G31 -> 2898182172 | H35: =H30-H32-H33-H31 -> 4107172649 | I35: =I30-I32-I33-I31 -> 3148242514 | ... K35: =K30-K32-K33-K31 -> 2607498597
A36: 资产减值准备 | B36: 108088278 | C36: 205314035 | D36: 140304975 | E36: 18976018 | F36: 30973964 | G36: 3939955 | H36: 50467105 | I36: 5124005 | J36: 11224597 | K36: 11540935
A37: 信用减值损失 | B37: 3562889 | C37: 17109861 | D37: 4092781 | E37: 5436372 | F37: 5986645 | G37: 20511657
A38: 固定资产折旧、油气资产折耗、生产性生物资产折旧 | B38: 2133735188 | C38: 2006016143 | D38: 1895051137 | E38: 1816292295 | F38: 1796451028 | G38: 1658464142 | H38: 1397193868 | I38: 1170550643 | J38: 1064314933 | K38: 876235955
A39: 使用权资产摊销 | B39: 168226551 | C39: 141396351 | D39: 122698462 | E39: 123037830 | F39: 118490311 | G39: 107566459
A40: 无形资产摊销 | B40: 90344881 | C40: 75882503 | D40: 68021416 | E40: 70365542 | F40: 72520085 | G40: 75727709 | H40: 50146297 | I40: 44348345 | J40: 42668547 | K40: 36109422
A41: 长期待摊费用摊销 | B41: 335192027 | C41: 299148362 | D41: 259296442 | E41: 241956999 | F41: 254543544 | G41: 288399999 | H41: 239827437 | I41: 183493510 | J41: 147684382 | K41: 119555034
A42: 处置固定资产、无形资产和其他长期资产的损失 | B42: 92206108 | C42: 100067948 | D42: 127946902 | E42: 103003542 | F42: 67154040 | G42: 9278127 | H42: 63298310 | I42: 26217990 | J42: 17315990 | K42: 65685144
A43: 固定资产报废损失
A44: 公允价值变动损失 | B44: -1941956 | C44: 1655540 | D44: 2033177 | E44: 9396901 | F44: 680484 | G44: 35747594 | H44: -63893463 | I44: 19118332 | J44: -2776702 | K44: 2808871
A45: 财务费用（收益以“－”号填列） | B45: -127999869 | C45: -156817467 | D45: -623268615 | E45: 567719920 | F45: 731090764 | G45: 323747885 | H45: 122942899 | I45: 496898960 | J45: -249338912 | K45: -109367084
A46: 投资损失（收益以“－”号填列） | B46: 60676479 | C46: 863478 | D46: -4598737 | E46: -77625641 | F46: -80920003 | G46: -92809928 | H46: -703300958 | I46: -23390958 | J46: -41956332 | K46: -23781843
A47: 递延所得税资产减少 | B47: 45971725 | C47: -15067352 | D47: 26958581 | E47: 87681484 | F47: -2105378 | G47: -266043908 | H47: 64287659 | I47: -87191702 | J47: 11244776 | K47: -14837203
...

Sheet 收入成本
B1: 2024 | C1: 2023 | D1: 2022 | E1: 2021 | F1: 2020 | G1: 2019 | H1: 2018 | I1: 2017 | J1: 2016 | K1: 2015
A2: 主营业务
A3: 收入 | B3: 38710428679 | C3: 32650176898 | D3: 27650978801 | E3: 23261134069 | F3: 19641289272 | G3: 20765088255 | H3: 19883838974 | I3: 18190913985 | J3: 16290566904 | K3: 13272702952
A4: 汽车玻璃 | B4: 35711992929 | C4: 29887354294 | D4: 25591272963 | E4: 21379623201 | F4: 17942033181 | G4: 18957337043 | H4: 19351888769 | I4: 17868123103
A5: 浮法玻璃 | B5: 5960560140 | C5: 5708192224 | D5: 4536714592 | E5: 4029400372 | F5: 3491541713 | G5: 3644797566 | H5: 3220524367 | I5: 2899053827
A6: 其他
A8: 成本 | B8: 24922427939 | C8: 21310091980 | D8: 18410110199 | E8: 15039848812 | F8: 11944882127 | G8: 13060926884 | H8: 11488667084 | I8: 10484369082 | J8: 9329573724 | K8: 7696406162
A9: 汽车玻璃 | B9: 24943534919 | C9: 20745955716 | D9: 18002483558 | E9: 14952938108 | F9: 11757642229 | G9: 12411825241 | H9: 12407230011 | I9: 11274474151
A10: 浮法玻璃 | B10: 3812209771 | C10: 4069450484 | D10: 3329138613 | E10: 2571070680 | F10: 2150493545 | G10: 2372599956 | H10: 1870957442 | I10: 1841648761
A12: 毛利 | B12: =B3-B8 -> 13788000740 | C12: =C3-C8 -> 11340084918 | D12: =D3-D8 -> 9240868602 | E12: =E3-E8 -> 8221285257 | F12: =F3-F8 -> 7696407145 | G12: =G3-G8 -> 7704161371 | H12: =H3-H8 -> 8395171890 | I12: =I3-I8 -> 7706544903 | ... K12: =K3-K8 -> 5576296790
A13: 汽车玻璃 | B13: =B4-B9 -> 10768458010 | C13: =C4-C9 -> 9141398578 | D13: =D4-D9 -> 7588789405 | E13: =E4-E9 -> 6426685093 | F13: =F4-F9 -> 6184390952 | G13: =G4-G9 -> 6545511802 | H13: =H4-H9 -> 6944658758 | I13: =I4-I9 -> 6593648952 | ... K13: =K4-K9 -> 0
A14: 浮法玻璃 | B14: =B5-B10 -> 2148350369 | C14: =C5-C10 -> 1638741740 | D14: =D5-D10 -> 1207575979 | E14: =E5-E10 -> 1458329692 | F14: =F5-F10 -> 1341048168 | G14: =G5-G10 -> 1272197610 | H14: =H5-H10 -> 1349566925 | I14: =I5-I10 -> 1057405066 | ... K14: =K5-K10 -> 0
A16: 其他业务
A17: 收入 | B17: 541228588 | C17: 510819743 | D17: 447775365 | E17: 341929292 | F17: 265304196 | G17: 338789268 | H17: 341146746 | I17: 522120989 | J17: 330769369 | K17: 300792103
A18: 成本 | B18: 108449502 | C18: 114234160 | D18: 125334935 | E18: 89204424 | F18: 97335416 | G18: 136627509 | H18: 114387863 | I18: 228242734 | J18: 133740207 | K18: 117937075
A19: 毛利 | B19: =B17-B18 -> 432779086 | C19: =C17-C18 -> 396585583 | D19: =D17-D18 -> 322440430 | E19: =E17-E18 -> 252724868 | F19: =F17-F18 -> 167968780 | G19: =G17-G18 -> 202161759 | H19: =H17-H18 -> 226758883 | I19: =I17-I18 -> 293878255 | ... K19: =K17-K18 -> 182855028
A22: YoY
A23: 收入 | B23: =B3/C3-1 -> 0.18561161 | C23: =C3/D3-1 -> 0.18079642 | D23: =D3/E3-1 -> 0.18872015 | E23: =E3/F3-1 -> 0.18429772 | F23: =F3/G3-1 -> -0.054119634 | G23: =G3/H3-1 -> 0.044319876 | H23: =H3/I3-1 -> 0.093064317 | I23: =I3/J3-1 -> 0.11665322 | J23: =J3/K3-1 -> 0.22737373
A24: 汽车玻璃 | B24: =B4/C4-1 -> 0.19488639 | C24: =C4/D4-1 -> 0.1678729 | D24: =D4/E4-1 -> 0.19699364 | E24: =E4/F4-1 -> 0.19159423 | F24: =F4/G4-1 -> -0.053557304 | G24: =G4/H4-1 -> -0.02038828 | H24: =H4/I4-1 -> 0.083039817 | I24: =I4/J4-1 -> #DIV/0! | J24: =J4/K4-1 -> #DIV/0!
A25: 浮法玻璃 | B25: =B5/C5-1 -> 0.044211531 | C25: =C5/D5-1 -> 0.25822158 | D25: =D5/E5-1 -> 0.12590316 | E25: =E5/F5-1 -> 0.15404618 | F25: =F5/G5-1 -> -0.042047837 | G25: =G5/H5-1 -> 0.13174041 | H25: =H5/I5-1 -> 0.11088809 | I25: =I5/J5-1 -> #DIV/0! | J25: =J5/K5-1 -> #DIV/0!
B27: =B3/I3 -> 2.128009
B28: =B4/I4 -> 1.9986427
B29: =B5/I5 -> 2.0560364

Sheet Beta_04
B1: 定价 | C1: 定价 | D1: 2024 | E1: 2023 | F1: 2022 | G1: 2021 | H1: 2020 | I1: 2019 | J1: 2018 | K1: 2017 | L1: 2016 | M1: 2015
A2: 资产 | D2: =balance!C2 -> 63254182536 | E2: =balance!D2 -> 56630407495 | F2: =balance!E2 -> 50767498791 | G2: =balance!F2 -> 44784893954 | H2: =balance!G2 -> 38423625184 | I2: =balance!H2 -> 38826279607 | J2: =balance!I2 -> 34490438670 | K2: =balance!J2 -> 31920898046 | ... M2: =balance!L2 -> 24640919497
A3: 现金 | D3: =balance!C4 -> 20713712160 | E3: =balance!D4 -> 19838830944 | F3: =balance!E4 -> 18165180172 | G3: =balance!F4 -> 15447688808 | H3: =balance!G4 -> 10411885641 | I3: =balance!H4 -> 10001551003 | J3: =balance!I4 -> 6800777265 | K3: =balance!J4 -> 6833689446 | ... M3: =balance!L4 -> 5918845168
A4: 投资 | D4: =balance!C10 -> 524177494 | E4: =balance!D10 -> 272592774 | F4: =balance!E10 -> 327607056 | G4: =balance!F10 -> 298144705 | H4: =balance!G10 -> 264748905 | I4: =balance!H10 -> 199805151 | J4: =balance!I10 -> 205738050 | K4: =balance!J10 -> 95519959 | ... M4: =balance!L10 -> 46449341
A5: 运营资产 | D5: =balance!C13 -> 16094542311 | E5: =balance!D13 -> 14147469320 | F5: =balance!E13 -> 12235113740 | G5: =balance!F13 -> 10129858419 | H5: =balance!G13 -> 8668361952 | I5: =balance!H13 -> 8471317618 | J5: =balance!I13 -> 9033666442 | K5: =balance!J13 -> 8680763546 | ... M5: =balance!L13 -> 6631629264
A6: 应收 | D6: =balance!C15+balance!C16 -> 8969464994 | E6: =balance!D15+balance!D16 -> 7496008772 | F6: =balance!E15+balance!E16 -> 5461966571 | G6: =balance!F15+balance!F16 -> 4350121771 | H6: =balance!G15+balance!G16 -> 3753925498 | I6: =balance!H15+balance!H16 -> 3477440317 | J6: =balance!I15+balance!I16 -> 4304107516 | K6: =balance!J15+balance!J16 -> 4637643979 | ... M6: =balance!L15+balance!L16 -> 3332153445
A7: 预付 | D7: =balance!C17 -> 305455256 | E7: =balance!D17 -> 316529520 | F7: =balance!E17 -> 235934604 | G7: =balance!F17 -> 238959820 | H7: =balance!G17 -> 173525313 | I7: =balance!H17 -> 222501827 | J7: =balance!I17 -> 220126772 | K7: =balance!J17 -> 195521295 | ... M7: =balance!L17 -> 178812459
A8: 存货 | D8: =balance!C14 -> 5970614068 | E8: =balance!D14 -> 5143615319 | F8: =balance!E14 -> 5403360356 | G8: =balance!F14 -> 4327048485 | H8: =balance!G14 -> 3280989599 | I8: =balance!H14 -> 3280465303 | J8: =balance!I14 -> 3241739977 | K8: =balance!J14 -> 2974677451 | ... M8: =balance!L14 -> 2815388428
A9: 长期资产 | D9: =balance!C25 -> 25921750571 | E9: =balance!D25 -> 22371514457 | F9: =balance!E25 -> 20039597823 | G9: =balance!F25 -> 18909202022 | H9: =balance!G25 -> 19078628686 | I9: =balance!H25 -> 20153605835 | J9: =balance!I25 -> 18450256913 | K9: =balance!J25 -> 16310925095 | ... M9: =balance!L25 -> 12043995724
A10: 负债 | D10: =balance!C33 -> 27568613358 | E10: =balance!D33 -> 25219085168 | F10: =balance!E33 -> 21779200663 | G10: =balance!F33 -> 18490789663 | H10: =balance!G33 -> 16832717886 | I10: =balance!H33 -> 17457198085 | J10: =balance!I33 -> 14300566064 | K10: =balance!J33 -> 13123026239 | ... M10: =balance!L33 -> 8411904960
A11: 预收 | D11: =balance!C39+balance!C38 -> 807312590 | E11: =balance!D39+balance!D38 -> 979067305 | F11: =balance!E39+balance!E38 -> 931585408 | G11: =balance!F39+balance!F38 -> 863737090 | H11: =balance!G39+balance!G38 -> 756282114 | I11: =balance!H39+balance!H38 -> 695400166 | J11: =balance!I39+balance!I38 -> 594503112 | K11: =balance!J39+balance!J38 -> 442282880 | ... M11: =balance!L39+balance!L38 -> 33985494
A12: 应付 | D12: =balance!C36+balance!C37 -> 5803094989 | E12: =balance!D36+balance!D37 -> 5522986739 | F12: =balance!E36+balance!E37 -> 4153709622 | G12: =balance!F36+balance!F37 -> 3148222805 | H12: =balance!G36+balance!G37 -> 2466005390 | I12: =balance!H36+balance!H37 -> 2097319605 | J12: =balance!I36+balance!I37 -> 2465349981 | K12: =balance!J36+balance!J37 -> 2401097118 | ... M12: =balance!L36+balance!L37 -> 1369271977
A13: 有息负债 | D13: =balance!C49 -> 14995298574 | E13: =balance!D49 -> 14535923962 | F13: =balance!E49 -> 13012009563 | G13: =balance!F49 -> 11205647043 | H13: =balance!G49 -> 10434585123 | I13: =balance!H49 -> 11383469538 | J13: =balance!I49 -> 8403278932 | K13: =balance!J49 -> 7920456975 | ... M13: =balance!L49 -> 4742619663
A14: 权益 | D14: =balance!C60 -> 35685569178 | E14: =balance!D60 -> 31411322327 | F14: =balance!E60 -> 28988298128 | G14: =balance!F60 -> 26294104291 | H14: =balance!G60 -> 21590907298 | I14: =balance!H60 -> 21369081522 | J14: =balance!I60 -> 20189872606 | K14: =balance!J60 -> 18797871807 | ... M14: =balance!L60 -> 16415066432
A15: 资本投入 | D15: =balance!C61+balance!C62 -> 12310494456 | E15: =balance!D61+balance!D62 -> 12310494456 | F15: =balance!E61+balance!E62 -> 12310494456 | G15: =balance!F61+balance!F62 -> 12310494456 | H15: =balance!G61+balance!G62 -> 8731529967 | I15: =balance!H61+balance!H62 -> 8731695689 | J15: =balance!I61+balance!I62 -> 8731695689 | K15: =balance!J61+balance!J62 -> 8732750629 | ... M15: =balance!L61+balance!L62 -> 8737549984
A16: 未分配利润 | D16: =balance!C66 -> 18625997091 | E16: =balance!D66 -> 15007163446 | F16: =balance!E66 -> 12989794025 | G16: =balance!F66 -> 11245487054 | H16: =balance!G66 -> 10305548562 | I16: =balance!H66 -> 9828694828 | J16: =balance!I66 -> 9150322858 | K16: =balance!J66 -> 8352285561 | ... M16: =balance!L66 -> 6599365793
A17: 股息分红 | D17: =balance!C71 -> 4.6975384e+09 | E17: =balance!D71 -> 3.3926666e+09 | F17: =balance!E71 -> 3262179415 | G17: =balance!F71 -> 2609743532 | H17: =balance!G71 -> 1957307649 | I17: =balance!H71 -> 1881463149 | J17: =balance!I71 -> 2884910162 | K17: =balance!J71 -> 1881463149 | ... M17: =balance!L71 -> 1881463149
A19: 现金结构 | D19: =D3 -> 20713712160 | E19: =E3 -> 19838830944 | F19: =F3 -> 18165180172 | G19: =G3 -> 15447688808 | H19: =H3 -> 10411885641 | I19: =I3 -> 10001551003 | J19: =J3 -> 6800777265 | K19: =K3 -> 6833689446 | ... M19: =M3 -> 5918845168
A20: 利润留存 | D20: =D16 -> 18625997091 | E20: =E16 -> 15007163446 | F20: =F16 -> 12989794025 | G20: =G16 -> 11245487054 | H20: =H16 -> 10305548562 | I20: =I16 -> 9828694828 | J20: =J16 -> 9150322858 | K20: =K16 -> 8352285561 | ... M20: =M16 -> 6599365793
A21: 股东、负债 | D21: =D19-D20 -> 2087715069 | E21: =E19-E20 -> 4831667498 | F21: =F19-F20 -> 5175386147 | G21: =G19-G20 -> 4202201754 | H21: =H19-H20 -> 106337079 | I21: =I19-I20 -> 172856175 | J21: =J19-J20 -> -2349545593 | K21: =K19-K20 -> -1518596115 | ... M21: =M19-M20 -> -680520625
A23: 折旧摊销 | D23: =SUM(损益现金流!B38:B41) -> 2727498647 | E23: =SUM(损益现金流!C38:C41) -> 2522443359 | F23: =SUM(损益现金流!D38:D41) -> 2345067457 | G23: =SUM(损益现金流!E38:E41) -> 2251652666 | H23: =SUM(损益现金流!F38:F41) -> 2242004968 | I23: =SUM(损益现金流!G38:G41) -> 2130158309 | J23: =SUM(损益现金流!H38:H41) -> 1687167602 | K23: =SUM(损益现金流!I38:I41) -> 1398392498 | ... M23: =SUM(损益现金流!K38:K41) -> 1031900411
A24: 资本开支 | D24: =损益现金流!B72 -> 5480872166 | E24: =损益现金流!C72 -> 4474711099 | F24: =损益现金流!D72 -> 3130253387 | G24: =损益现金流!E72 -> 2328511864 | H24: =损益现金流!F72 -> 1772542963 | I24: =损益现金流!G72 -> 2779502262 | J24: =损益现金流!H72 -> 3591741242 | K24: =损益现金流!I72 -> 3589995076 | ... M24: =损益现金流!K72 -> 3255541569
A26: 股本 | B26: =D26 -> 2609743532 | C26: =D26 -> 2609743532 | D26: =balance!C61 -> 2609743532 | E26: =balance!D61 -> 2609743532 | F26: =balance!E61 -> 2609743532 | G26: =balance!F61 -> 2609743532 | H26: =balance!G61 -> 2508617532 | I26: =balance!H61 -> 2508617532 | J26: =balance!I61 -> 2508617532 | K26: =balance!J61 -> 2508617532 | ... M26: =balance!L61 -> 2508617532
A28: 主营收入 | D28: =收入成本!B3 -> 38710428679 | E28: =收入成本!C3 -> 32650176898 | F28: =收入成本!D3 -> 27650978801 | G28: =收入成本!E3 -> 23261134069 | H28: =收入成本!F3 -> 19641289272 | I28: =收入成本!G3 -> 20765088255 | J28: =收入成本!H3 -> 19883838974 | K28: =收入成本!I3 -> 18190913985 | ... M28: =收入成本!K3 -> 13272702952
A29: 主营成本 | D29: =收入成本!B8 -> 24922427939 | E29: =收入成本!C8 -> 21310091980 | F29: =收入成本!D8 -> 18410110199 | G29: =收入成本!E8 -> 15039848812 | H29: =收入成本!F8 -> 11944882127 | I29: =收入成本!G8 -> 13060926884 | J29: =收入成本!H8 -> 11488667084 | K29: =收入成本!I8 -> 10484369082 | ... M29: =收入成本!K8 -> 7696406162
A30: 费用 | D30: =SUM(损益现金流!B5:B8) -> 6032289023 | E30: =SUM(损益现金流!C5:C8) -> 5667759562 | F30: =SUM(损益现金流!D5:D8) -> 4967587622 | G30: =SUM(损益现金流!E5:E8) -> 4297003585 | H30: =SUM(损益现金流!F5:F8) -> 4564753107 | I30: =SUM(损益现金流!G5:G8) -> 4677876806 | J30: =SUM(损益现金流!H5:H8) -> 4621537694 | K30: =SUM(损益现金流!I5:I8) -> 4075393078 | ... M30: =SUM(损益现金流!K5:K8) -> 3006403460
A31: 研发费用 | D31: =损益现金流!B8 -> 1677751298 | E31: =损益现金流!C8 -> 1403030121 | F31: =损益现金流!D8 -> 1248592812 | G31: =损益现金流!E8 -> 997203019 | H31: =损益现金流!F8 -> 815579258 | I31: =损益现金流!G8 -> 813129835 | J31: =损益现金流!H8 -> 887721987 | K31: =损益现金流!I8 -> 803441192 | ... M31: =损益现金流!K8 -> 0
A32: 销售费用 | D32: =损益现金流!B6 -> 1180260909 | E32: =损益现金流!C6 -> 1538783486 | F32: =损益现金流!D6 -> 1350721298 | G32: =损益现金流!E6 -> 1150992397 | H32: =损益现金流!F6 -> 1474366072 | I32: =损益现金流!G6 -> 1481567161 | J32: =损益现金流!H6 -> 1467671276 | K32: =损益现金流!I6 -> 1274308845 | ... M32: =损益现金流!K6 -> 1020584621
A33: 管理费用 | D33: =损益现金流!B7 -> 2888289768 | E33: =损益现金流!C7 -> 2486049334 | F33: =损益现金流!D7 -> 2142932036 | G33: =损益现金流!E7 -> 1944179027 | H33: =损益现金流!F7 -> 2076624937 | I33: =损益现金流!G7 -> 2185363063 | J33: =损益现金流!H7 -> 2063072209 | K33: =损益现金流!I7 -> 1797379424 | ... M33: =损益现金流!K7 -> 1873364984
A34: 损耗 | D34: =SUM(损益现金流!B11:B13) -> -98548679 | E34: =SUM(损益现金流!C11:C13) -> -220776671 | F34: =SUM(损益现金流!D11:D13) -> -150481522 | G34: =SUM(损益现金流!E11:E13) -> -23928049 | H34: =SUM(损益现金流!F11:F13) -> 38157119 | I34: =SUM(损益现金流!G11:G13) -> -20103858 | J34: =SUM(损益现金流!H11:H13) -> -51746308 | K34: =SUM(损益现金流!I11:I13) -> -31328690 | ... M34: =SUM(损益现金流!K11:K13) -> -11540935
A35: 其他收益 | D35: =损益现金流!B10 -> 400415185 | E35: =损益现金流!C10 -> 262917177 | F35: =损益现金流!D10 -> 215071387 | G35: =损益现金流!E10 -> 242337506 | H35: =损益现金流!F10 -> 352820556 | I35: =损益现金流!G10 -> 181754102 | J35: =损益现金流!H10 -> 146750220 | K35: =损益现金流!I10 -> 190690589 | ... M35: =损益现金流!K10 -> 0
A36: 现金收益 | D36: =损益现金流!B20 -> 924966003 | E36: =损益现金流!C20 -> 602544066 | F36: =损益现金流!D20 -> 231495735 | G36: =损益现金流!E20 -> 195413923 | H36: =损益现金流!F20 -> 348762592 | I36: =损益现金流!G20 -> 336984661 | J36: =损益现金流!H20 -> 335452093 | K36: =损益现金流!I20 -> 137540567 | ... M36: =损益现金流!K20 -> 16915996
A37: 股权收益 | D37: =损益现金流!B25 -> -15801862 | E37: =损益现金流!C25 -> 4290148 | F37: =损益现金流!D25 -> 20962737 | G37: =损益现金流!E25 -> 26975045 | H37: =损益现金流!F25 -> 11843754 | I37: =损益现金流!G25 -> -5932899 | J37: =损益现金流!H25 -> 667776495 | K37: =损益现金流!I25 -> 23390958 | ... M37: =损益现金流!K25 -> 23781843
A38: 利息支出 | D38: =损益现金流!B31 -> 288507082 | E38: =损益现金流!C31 -> 288319603 | F38: =损益现金流!D31 -> 288122259 | G38: =损益现金流!E31 -> 318940791 | H38: =损益现金流!F31 -> 354752403 | I38: =损益现金流!G31 -> 432679520 | J38: =损益现金流!H31 -> 376230473 | K38: =损益现金流!I31 -> 182373020 | ... M38: =损益现金流!K31 -> 190512029
A39: 财务费用 | D39: =损益现金流!B32 -> 35964048 | E39: =损益现金流!C32 -> -361719066 | F39: =损益现金流!D32 -> -1036725297 | G39: =损益现金流!E32 -> 536834250 | H39: =损益现金流!F32 -> 429822814 | I39: =损益现金流!G32 -> -127469129 | J39: =损益现金流!H32 -> -250823052 | K39: =损益现金流!I32 -> 393023828 | ... M39: =损益现金流!K32 -> -459846707
A40: 其他业务
A41: 收入 | D41: =收入成本!B17 -> 541228588 | E41: =收入成本!C17 -> 510819743 | F41: =收入成本!D17 -> 447775365 | G41: =收入成本!E17 -> 341929292 | H41: =收入成本!F17 -> 265304196 | I41: =收入成本!G17 -> 338789268 | J41: =收入成本!H17 -> 341146746 | K41: =收入成本!I17 -> 522120989 | ... M41: =收入成本!K17 -> 300792103
A42: 成本 | D42: =收入成本!B18 -> 108449502 | E42: =收入成本!C18 -> 114234160 | F42: =收入成本!D18 -> 125334935 | G42: =收入成本!E18 -> 89204424 | H42: =收入成本!F18 -> 97335416 | I42: =收入成本!G18 -> 136627509 | J42: =收入成本!H18 -> 114387863 | K42: =收入成本!I18 -> 228242734 | ... M42: =收入成本!K18 -> 117937075
A43: 营业外
A44: 收入 | D44: =损益现金流!B15 -> 35905331 | E44: =损益现金流!C15 -> 49843149 | F44: =损益现金流!D15 -> 80855034 | G44: =损益现金流!E15 -> 217974835 | H44: =损益现金流!F15 -> 57628048 | I44: =损益现金流!G15 -> 109494454 | J44: =损益现金流!H15 -> 60687441 | K44: =损益现金流!I15 -> 27172108 | ... M44: =损益现金流!K15 -> 129935252
...
