Workbook

Sheet balance sheet（处理后）
C1: 2024.12.31 | D1: 2023.12.31 | E1: 2022.12.31 | F1: 2021.12.31 | G1: 2020.12.31 | H1: 2019.12.31
A2: 资产 | C2: =C3+C10+C15+C26 -> 1.5912889e+10 | D2: =D3+D10+D15+D26 -> 1.3974021e+10 | E2: =E3+E10+E15+E26 -> 1.2057677e+10 | F2: =F3+F10+F15+F26 -> 1.0425669e+10 | G2: =G3+G10+G15+G26 -> 8.5115862e+09 | H2: =H3+H10+H15+H26 -> 6.8439935e+09
A3: 金融资产 | C3: =SUM(C4:C8) -> 1.2812479e+10 | D3: =SUM(D4:D8) -> 1.1392118e+10 | E3: =SUM(E4:E8) -> 1.0293767e+10 | F3: =SUM(F4:F8) -> 9.2193082e+09 | G3: =SUM(G4:G8) -> 7.6442103e+09 | H3: =SUM(H4:H8) -> 6.2955176e+09
B4: 货币资金 | C4: 8.9793629e+08 | D4: 3.4781593e+09 | E4: 7.0154461e+09 | F4: 1.2539586e+09 | G4: 1.0035041e+09 | H4: 7.4923668e+08
B5: 交易性金融资产 | C5: 1.3841518e+09 | D5: 2.5707621e+09 | H5: 15500000
B6: 理财产品 | E6: 1.1921074e+09 | F6: 6.9418323e+09 | G6: 6.6254452e+09 | H6: 5.5206946e+09
B7: 定期存款/利息 | C7: =3168225913.95+7343591355.88 -> 1.0511817e+10 | D7: =1154634585.44+2249205659.64+1918453672.93 -> 5.3222939e+09 | E7: =962979425.76+1123233771.41 -> 2.0862132e+09 | F7: =150575.44+1023366805.62 -> 1.0235174e+09 | G7: 192343.26 | H7: 280.31
B8: 其他非流动金融资产 | C8: 18573510 | D8: 20902460 | G8: 15068687 | H8: 10086000
A10: 长期股权投资 | C10: =SUM(C11:C13) -> 1.5837826e+09 | D10: =SUM(D11:D13) -> 1.1148938e+09 | E10: =SUM(E11:E13) -> 4.913314e+08 | F10: =SUM(F11:F13) -> 1.6841795e+08 | G10: =SUM(G11:G13) -> 53083238 | H10: =SUM(H11:H13) -> 38612671
B11: 长期股权投资 | C11: 1.5630075e+09 | D11: 1.0940629e+09 | E11: 4.4409524e+08 | F11: 1.2319479e+08 | G11: 35832545 | H11: 21856850
B12: 其他权益工具投资 | C12: 19967434 | D12: 19754308 | E12: 19615452 | F12: 8800620 | G12: 9058955.2 | H12: 9642362.3
B13: 其他非流动金融资产（权益工具） | C13: 807695.81 | D13: 1076527.9 | E13: 27620704 | F13: 36422542 | G13: =6191738.29+2000000 -> 8191738.3 | H13: =7113458.54 -> 7113458.5
A15: 经营资产 | C15: =SUM(C16:C24) -> 7.2816093e+08 | D15: =SUM(D16:D24) -> 7.6115434e+08 | E15: =SUM(E16:E24) -> 647433732 | F15: =SUM(F16:F24) -> 5.3505509e+08 | G15: =SUM(G16:G24) -> 4.961692e+08 | H15: =SUM(H16:H24) -> 4.1410836e+08
B16: 应收票据 | C16: 5309651.7 | D16: 2080000 | E16: 3447750 | F16: 3667000 | G16: 2340900 | H16: 2086153.9
B17: 应收帐款 | C17: 5.0456706e+08 | D17: 5.6694035e+08 | E17: 4.9679152e+08 | F17: 4.1153132e+08 | G17: 3.9810848e+08 | H17: 3.4502336e+08
B18: 预付款项 | C18: 13981930 | D18: 21957493 | E18: 27596962 | F18: 25601542 | G18: 8383888.8 | H18: 5322052.8
B19: 其他应收款 | C19: 69650288 | D19: 49547645 | E19: 27086472 | F19: =36082150.16 -> 36082150 | G19: 41018315 | H19: 25502706
B20: 存货 | C20: 802036.62 | D20: 1412787.6 | E20: 1157966.9 | F20: 2296705.1 | G20: 1347945.7 | H20: 1428104.1
B21: 合同资产 | C21: 263087.25 | D21: 1627986.9 | E21: 2151316.3 | F21: 2293113.3
B22: 其他流动资产 | C22: 59813764 | D22: 50632903 | E22: =2005683.48+21437102.5+23108553.53 -> 46551340 | F22: 16749539 | G22: 7831649.1 | H22: 15766894
B23: 其他非流动资产 | C23: =16902633.88+21893267.98 -> 38795902 | D23: =15847661.8+10379190.9 -> 26226853 | E23: =13808232.72+7716198.73 -> 21524431 | F23: =7196666+10583485.34 -> 17780151 | G23: 21358676 | H23: 3919100
B24: 递延所得税资产 | C24: 34977206 | D24: 40728324 | E24: 21125978 | F24: 19053561 | G24: 15779343 | H24: 15059985
A26: 长期资产 | C26: =SUM(C27:C32) -> 7.8846634e+08 | D26: =SUM(D27:D32) -> 7.0585543e+08 | E26: =SUM(E27:E32) -> 6.2514484e+08 | F26: =SUM(F27:F32) -> 5.0288813e+08 | G26: =SUM(G27:G32) -> 3.1812341e+08 | H26: =SUM(H27:H32) -> 95754892
B27: 固定资产 | C27: 2.9665123e+08 | D27: 68991108 | E27: 82420787 | F27: 88342058 | G27: 61686373 | H27: 67165132
B28: 在建工程 | C28: 1.3495944e+08 | D28: 2.4805629e+08 | E28: 1.2064613e+08
B29: 使用权资产 | C29: 43404511 | D29: 70889834 | E29: 1.0705335e+08 | F29: 99376293
B30: 无形资产 | C30: 79351285 | D30: 87027526 | E30: 1.0229323e+08 | F30: 1.1798333e+08 | G30: 59044733 | H30: 17609109
B31: 商誉 | C31: 1.8466897e+08 | D31: 1.8466897e+08 | E31: 1.8466897e+08 | F31: 1.8466897e+08 | G31: 1.8466897e+08
B32: 长期待摊费用 | C32: 49430909 | D32: 46221703 | E32: 28062368 | F32: 12517470 | G32: 12723328 | H32: 10980651
A34: 负债 | C34: =C35+C49+C52 -> 4.4763191e+09 | D34: =D35+D49+D52 -> 3.9544151e+09 | E34: =E35+E49+E52 -> 3.2592856e+09 | F34: =F35+F49+F52 -> 2.6454601e+09 | G34: =G35+G49+G52 -> 1.6207629e+09 | H34: =H35+H49+H52 -> 7.7541323e+08
A35: 经营负债 | C35: =SUM(C36:C47) -> 4.363218e+09 | D35: =SUM(D36:D47) -> 3876009543 | E35: =SUM(E36:E47) -> 3.1240163e+09 | F35: =SUM(F36:F47) -> 2.5309469e+09 | G35: =SUM(G36:G47) -> 1.6207629e+09 | H35: =SUM(H36:H47) -> 7.7541323e+08
B36: 应付账款 | C36: 4.458657e+08 | D36: 4.5348455e+08 | E36: 3.0630474e+08 | F36: 2.1219664e+08 | G36: 1.4038947e+08 | H36: 60235681
B37: 预收款项 | H37: 4.3767363e+08
B38: 合同负债 | C38: 2.1355359e+09 | D38: 1.8918741e+09 | E38: 1.7312476e+09 | F38: 1.420876e+09 | G38: 8.3275063e+08
B39: 应付职工薪酬 | C39: 4.8106591e+08 | D39: 4.6359106e+08 | E39: 3.9433263e+08 | F39: 3.6030722e+08 | G39: 2.4994716e+08 | H39: 1.5529453e+08
B40: 应交税费 | C40: 80085593 | D40: 70268323 | E40: 45606445 | F40: 55460575 | G40: 1.1242866e+08 | H40: 37890686
B41: 其他应付款 | C41: 1.1666246e+08 | D41: 1.0367197e+08 | E41: 97531167 | F41: 90666378 | G41: 49333920 | H41: 35618022
B42: 其他流动负债 | C42: 1.0721531e+08 | D42: 1.3416301e+08 | E42: 1.0935069e+08 | F42: 88406222 | G42: 52964852
B43: 长期应付款 | D43: 56710317 | E43: 51723271 | F43: 47174781
B44: 预计负债 | D44: 10000000
...

Sheet balance
C1: 2024.12.31 | D1: 2023.12.31 | E1: 2022.12.31 | F1: 2021.12.31 | G1: 2020.12.31 | H1: 2019.12.31
A2: 资产 | C2: =C3+C11+C15+C25 -> 1.5912889e+10 | D2: =D3+D11+D15+D25 -> 1.3974021e+10 | E2: =E3+E11+E15+E25 -> 1.2057677e+10 | F2: =F3+F11+F15+F25 -> 1.0425669e+10 | G2: =G3+G11+G15+G25 -> 8.5115862e+09 | H2: =H3+H11+H15+H25 -> 6.8439935e+09
A3: 金融资产 | C3: =SUM(C4:C8) -> 1.2832701e+10 | D3: =SUM(D4:D8) -> 1.1397442e+10 | E3: =SUM(E4:E8) -> 1.0315291e+10 | F3: =SUM(F4:F9) -> 9.2370884e+09 | G3: =SUM(G4:G9) -> 7.6505003e+09 | H3: =SUM(H4:H9) -> 6.2893507e+09
B4: 货币资金 | C4: 8.9793629e+08 | D4: 3.4781593e+09 | E4: 7.0154461e+09 | F4: 1.2539586e+09 | G4: 1.0035041e+09 | H4: 7.4923668e+08
B5: 交易性金融资产 | C5: 1.3841518e+09 | D5: 2.5707621e+09 | E5: 1.1921074e+09 | F5: 6.9418323e+09 | G5: 6.6254452e+09 | H5: 5.5361946e+09
B6: 一年内到期的非流动资产 | C6: 77313613 | D6: 1.1546346e+09
B7: 其他流动资产 | C7: 3.0909123e+09 | D7: 2.2492057e+09 | E7: 9.6297943e+08
B8: 其他非流动资产 | C8: 7.3823873e+09 | D8: 1.9446805e+09 | E8: 1.1447582e+09 | F8: 1.041147e+09 | G8: 21358676 | H8: 3919100
B9: 应收利息 | F9: 150575.44 | G9: 192343.26 | H9: 280.31
A11: 长期股权投资 | C11: =SUM(C12:C14) -> 1.6023561e+09 | D11: =SUM(D12:D14) -> 1.1357962e+09 | E11: =SUM(E12:E14) -> 4.913314e+08 | F11: =SUM(F12:F14) -> 1.6841795e+08 | G11: =SUM(G12:G14) -> 68151925 | H11: =SUM(H12:H14) -> 48698671
B12: 长期股权投资 | C12: 1.5630075e+09 | D12: 1.0940629e+09 | E12: 4.4409524e+08 | F12: 1.2319479e+08 | G12: 35832545 | H12: 21856850
B13: 其他权益工具投资 | C13: 19967434 | D13: 19754308 | E13: 19615452 | F13: 8800620 | G13: 9058955.2 | H13: 9642362.3
B14: 其他非流动金融资产 | C14: 19381206 | D14: 21978988 | E14: 27620704 | F14: 36422542 | G14: 23260425 | H14: 17199459
A15: 经营资产 | C15: =SUM(C16:C23) -> 6.8936502e+08 | D15: =SUM(D16:D23) -> 7.3492749e+08 | E15: =SUM(E16:E23) -> 6.259093e+08 | F15: =SUM(F16:F23) -> 5.1727494e+08 | G15: =SUM(G16:G23) -> 4.7481052e+08 | H15: =SUM(H16:H23) -> 4.1018926e+08
B16: 应收票据 | C16: 5309651.7 | D16: 2080000 | E16: 3447750 | F16: 3667000 | G16: 2340900 | H16: 2086153.9
B17: 应收帐款 | C17: 5.0456706e+08 | D17: 5.6694035e+08 | E17: 4.9679152e+08 | F17: 4.1153132e+08 | G17: 3.9810848e+08 | H17: 3.4502336e+08
B18: 预付款项 | C18: 13981930 | D18: 21957493 | E18: 27596962 | F18: 25601542 | G18: 8383888.8 | H18: 5322052.8
B19: 其他应收款 | C19: 69650288 | D19: 49547645 | E19: 27086472 | F19: =36232725.6-F9 -> 36082150 | G19: =41210658.13-G9 -> 41018315 | H19: =25502986.03-H9 -> 25502706
B20: 存货 | C20: 802036.62 | D20: 1412787.6 | E20: 1157966.9 | F20: 2296705.1 | G20: 1347945.7 | H20: 1428104.1
B21: 合同资产 | C21: 263087.25 | D21: 1627986.9 | E21: 2151316.3 | F21: 2293113.3
B22: 其他流动资产 | C22: 59813764 | D22: 50632903 | E22: =1009530765.27-E7 -> 46551340 | F22: 16749539 | G22: 7831649.1 | H22: 15766894
B23: 递延所得税资产 | C23: 34977206 | D23: 40728324 | E23: 21125978 | F23: 19053561 | G23: 15779343 | H23: 15059985
A25: 长期资产 | C25: =SUM(C26:C31) -> 7.8846634e+08 | D25: =SUM(D26:D31) -> 7.0585543e+08 | E25: =SUM(E26:E31) -> 6.2514484e+08 | F25: =SUM(F26:F31) -> 5.0288813e+08 | G25: =SUM(G26:G31) -> 3.1812341e+08 | H25: =SUM(H26:H31) -> 95754892
B26: 固定资产 | C26: 2.9665123e+08 | D26: 68991108 | E26: 82420787 | F26: 88342058 | G26: 61686373 | H26: 67165132
B27: 在建工程 | C27: 1.3495944e+08 | D27: 2.4805629e+08 | E27: 1.2064613e+08
B28: 使用权资产 | C28: 43404511 | D28: 70889834 | E28: 1.0705335e+08 | F28: 99376293
B29: 无形资产 | C29: 79351285 | D29: 87027526 | E29: 1.0229323e+08 | F29: 1.1798333e+08 | G29: 59044733 | H29: 17609109
B30: 商誉 | C30: 1.8466897e+08 | D30: 1.8466897e+08 | E30: 1.8466897e+08 | F30: 1.8466897e+08 | G30: 1.8466897e+08
B31: 长期待摊费用 | C31: 49430909 | D31: 46221703 | E31: 28062368 | F31: 12517470 | G31: 12723328 | H31: 10980651
A33: 负债 | C33: =C34+C48+C51 -> 4.4763191e+09 | D33: =D34+D48+D51 -> 3.9544151e+09 | E33: =E34+E48+E51 -> 3.2592856e+09 | F33: =F34+F48+F51 -> 2.6454601e+09 | G33: =G34+G48+G51 -> 1.6207629e+09 | H33: =H34+H48+H51 -> 7.7541323e+08
A34: 经营负债 | C34: =SUM(C35:C46) -> 4.363218e+09 | D34: =SUM(D35:D46) -> 3876009543 | E34: =SUM(E35:E46) -> 3.1240163e+09 | F34: =SUM(F35:F46) -> 2.5309469e+09 | G34: =SUM(G35:G46) -> 1.6207629e+09 | H34: =SUM(H35:H46) -> 7.7541323e+08
B35: 应付账款 | C35: 4.458657e+08 | D35: 4.5348455e+08 | E35: 3.0630474e+08 | F35: 2.1219664e+08 | G35: 1.4038947e+08 | H35: 60235681
B36: 预收款项 | H36: 4.3767363e+08
B37: 合同负债 | C37: 2.1355359e+09 | D37: 1.8918741e+09 | E37: 1.7312476e+09 | F37: 1.420876e+09 | G37: 8.3275063e+08
B38: 应付职工薪酬 | C38: 4.8106591e+08 | D38: 4.6359106e+08 | E38: 3.9433263e+08 | F38: 3.6030722e+08 | G38: 2.4994716e+08 | H38: 1.5529453e+08
B39: 应交税费 | C39: 80085593 | D39: 70268323 | E39: 45606445 | F39: 55460575 | G39: 1.1242866e+08 | H39: 37890686
B40: 其他应付款 | C40: 1.1666246e+08 | D40: 1.0367197e+08 | E40: 97531167 | F40: 90666378 | G40: 49333920 | H40: 35618022
B41: 其他流动负债 | C41: 1.0721531e+08 | D41: 1.3416301e+08 | E41: 1.0935069e+08 | F41: 88406222 | G41: 52964852
B42: 长期应付款 | D42: 56710317 | E42: 51723271 | F42: 47174781
B43: 预计负债 | D43: 10000000
...

Sheet 损益现金流
B1: 2024 | C1: 2023 | D1: 2022 | E1: 2021 | F1: 2020 | G1: 2019
A2: 营收 | B2: 5.1208388e+09 | C2: 4.5559683e+09 | D2: 3.8849595e+09 | E2: 3.2800588e+09 | F2: 2.2609684e+09 | G2: 1.5795206e+09
A3: 营业成本 | B3: 7.6076192e+08 | C3: 6.6984014e+08 | D3: 5.8291066e+08 | E3: 4.2935278e+08 | F3: 2.7813494e+08 | G3: 2.2776573e+08
A4: 毛利率 | B4: =1-B3/B2 -> 0.85143803 | C4: =1-C3/C2 -> 0.85297524 | D4: =1-D3/D2 -> 0.84995708 | E4: =1-E3/E2 -> 0.86910211 | F4: =1-F3/F2 -> 0.87698415 | G4: =1-G3/G2 -> 0.85580072
A5: 税金及附加 | B5: 49170365 | C5: 37161428 | D5: 34743722 | E5: 35179114 | F5: 22921921 | G5: 15936651
A6: 销售费用 | B6: 9.9133253e+08 | C6: 9.6741454e+08 | D6: 8.1820166e+08 | E6: 6.9497017e+08 | F6: 4.8280766e+08 | G6: 3.4473805e+08
A7: 管理费用 | B7: 4.0266289e+08 | C7: 4.4422792e+08 | D7: 3.9190309e+08 | E7: 3.2600319e+08 | F7: 2.1254109e+08 | G7: 1.356965e+08
A8: 研发费用 | B8: 1.6955569e+09 | C8: 1.4722958e+09 | D8: 1.3312108e+09 | E8: 1.081625e+09 | F8: 7.1088189e+08 | G8: 5.9878566e+08
A9: 信用减值 | B9: -15949603 | C9: -16113383 | D9: 2060333.2 | E9: -11630385 | F9: -4182207.5 | G9: -7056972.4
A10: 资产减值 | B10: -8018423.9 | C10: -7155150.3 | D10: -27214231 | E10: -70419.47 | G10: -31084.2
A11: 资产处置 | B11: 181735.73 | C11: 5242488.1 | D11: 160353.87 | E11: 181433.17 | F11: 16587.47 | G11: 2708.67
A12: 其他收益 | B12: 1.7612308e+08 | C12: 1.42203e+08 | D12: 1.7304803e+08 | E12: 1.9860388e+08 | F12: 1.1471942e+08 | G12: 67353894
A13: 营业外收入 | B13: 3918649.7 | C13: 1470784 | D13: 2197939.3 | E13: 3618260.6 | F13: 807603.11
A14: 营业外支出 | B14: -5455007.3 | C14: 12211502 | D14: 517546.52 | E14: 6203330.7 | F14: 318305.79 | G14: -4724895.3
A15: 息税前经营收益 | B15: =B2-B3-SUM(B5:B8)+SUM(B9:B12)+B13-B14 -> 1.3830647e+09 | C15: =C2-C3-SUM(C5:C8)+SUM(C9:C12)+C13-C14 -> 1.0784647e+09 | D15: =D2-D3-SUM(D5:D8)+SUM(D9:D12)+D13-D14 -> 8.7572438e+08 | E15: =E2-E3-SUM(E5:E8)+SUM(E9:E12)+E13-E14 -> 8.9742797e+08 | F15: =F2-F3-SUM(F5:F8)+SUM(F9:F12)+F13-F14 -> 6.6472399e+08 | G15: =G2-G3-SUM(G5:G8)+SUM(G9:G12)+G13-G14 -> 3.2159146e+08
A16: 短期投资收益 | B16: =222158992.8+68762441.84 -> 2.9092143e+08 | C16: =136522034.04+48306921.09 -> 1.8482896e+08 | D16: =189331686.85+77913125.38 -> 2.6724481e+08 | E16: =179922006.63+144658+39731468.87 -> 2.1979813e+08 | F16: =85884376.34+-17907666.67 -> 67976710 | G16: 22832600
A17: 利息收入 | B17: 26432907 | C17: 1.0500676e+08 | D17: 23567706 | E17: 23972438 | F17: 10459654 | G17: 3852556.2
A18: 公允价值变动收益 | B18: =-14547752.34+-3551325.24 -> -18099078 | C18: =6757892.24+-8857233.23 -> -2099341 | D18: =-18984506.87+-5449992.67 -> -24434500 | E18: =-1488669.41+-47825.19 -> -1536494.6 | F18: =115970430.02+2112747.79 -> 1.1808318e+08 | G18: =31977675.53+18277000 -> 50254676
A19: 息税前金融资产收益 | B19: =SUM(B16:B18) -> 2.9925526e+08 | C19: =SUM(C16:C18) -> 2.8773638e+08 | D19: =SUM(D16:D18) -> 2.6637802e+08 | E19: =SUM(E16:E18) -> 2.4223408e+08 | F19: =SUM(F16:F18) -> 1.9651954e+08 | G19: =SUM(G16:G18) -> 76939832
A20: 长期股权收益 | B20: 79011534 | C20: 34333675 | D20: =72734416.41+-735306.57 -> 71999110 | E20: =-14617190.94 -> -14617191 | F20: =-9056226.29+85244610.72 -> 76188384 | G20: 8633041.9
A21: （权益工具）公允价值变动收益 | B21: -288123.06 | C21: -527775.08 | D21: -5276061.5 | E21: 468650.3 | F21: -519287.32 | G21: 41284.67
A22: 长期投资收益 | B22: =SUM(B20:B21) -> 78723411 | C22: =SUM(C20:C21) -> 33805900 | D22: =SUM(D20:D21) -> 66723048 | E22: =SUM(E20:E21) -> -14148541 | F22: =SUM(F20:F21) -> 75669097 | G22: =SUM(G20:G21) -> 8674326.6
A23: 息税前利润总额 | B23: =B15+B19+B22 -> 1.7610434e+09 | C23: =C15+C19+C22 -> 1.4000069e+09 | D23: =D15+D19+D22 -> 1.2088255e+09 | E23: =E15+E19+E22 -> 1.1255135e+09 | F23: =F15+F19+F22 -> 9.3691262e+08 | G23: =G15+G19+G22 -> 4.0720562e+08
A24: 利息支出
A25: 财务费用 | B25: 10620632 | C25: 10167473 | D25: =-(12984610.32-D17) -> 10583095 | E25: =-(17169875.92-E17) -> 6802562.5 | F25: =-(9410173.68-F17) -> 1049480.2 | G25: =-(3018936.31-G17) -> 833619.92
A26: 税前利润总额 | B26: =B23-B25 -> 1.7504227e+09 | C26: =C23-C25 -> 1.3898395e+09 | D26: =D23-D25 -> 1.1982424e+09 | E26: =E23-E25 -> 1.1187109e+09 | F26: =F23-F25 -> 9.3586314e+08 | G26: =G23-G25 -> 4.06372e+08
A27: 所得税 | B27: 95138661 | C27: 75377801 | D27: 67317889 | E27: 49759284 | F27: 49289324 | G27: 5792795.7
A28: 净利润 | B28: =B26-B27 -> 1.6552841e+09 | C28: =C26-C27 -> 1.3144617e+09 | D28: =D26-D27 -> 1.1309245e+09 | E28: =E26-E27 -> 1.0689517e+09 | F28: =F26-F27 -> 8.8657382e+08 | G28: =G26-G27 -> 4.005792e+08
A29: 资产减值准备 | B29: 8018423.9 | C29: 7155150.3 | D29: 27214231 | E29: 70419.47 | G29: 31084.2
A30: 信用减值损失 | B30: 15949603 | C30: 16113383 | D30: -2060333.2 | E30: 11630385 | F30: 4182207.5 | G30: 7056972.4
A31: 资产折旧 | B31: 44432135 | C31: 46721679 | D31: 50377053 | E31: 44287050 | F31: 35723226 | G31: 24893376
A32: 使用权资产折旧 | B32: 42483264 | C32: 44165518 | D32: 46994619 | E32: 27773694
A33: 无形资产摊销 | B33: 19446866 | C33: 24971096 | D33: 25979497 | E33: 20169464 | F33: 9325331.1 | G33: 4511920.1
A34: 长期待摊 | B34: 8489518.3 | C34: 8662878.2 | D34: 6996903.8 | E34: 3309754.1 | F34: 2079507.6 | G34: 2731276.6
A35: 固定资产损失 | B35: -181735.73 | C35: -5242488.1 | D35: -160353.87 | E35: -186023.09 | F35: -16587.47 | G35: -2708.67
A36: 固定资产报废 | C36: -91442 | D36: -21106.11 | F36: 7654.87
A37: 公允价值变动损失 | B37: 18387201 | C37: 2627116.1 | D37: 29710561 | E37: 1067844.3 | F37: -1.1756389e+08 | G37: -50295960
A38: 财务费用 | B38: 8664291.3 | C38: 9274711.4 | D38: 10327234 | E38: 5917385.2 | F38: 773218.68 | G38: 626534.81
A39: 投资损失 | B39: -3.6993297e+08 | C39: -2.1916263e+08 | D39: -3.3924392e+08 | E39: -2.0518094e+08 | F39: -1.4416509e+08 | G39: -31465642
A40: 递延所得税资产减少 | B40: 4344376.5 | C40: -4776914.1 | D40: -2072417.3 | E40: -3274217.8 | F40: -580753.66 | G40: 2040618.8
...

Sheet 营运资本变动
A1: 账面余额
B2: 2024.12.31 | C2: 2023.12.31 | D2: 2022.12.31 | E2: 2021.12.31 | F2: 2020.12.31 | G2: 2019.12.31
A3: 应收
A4: 应收票据 | B4: 5309651.7 | C4: 2080000 | D4: 3447750 | E4: 3667000 | F4: 2340900 | G4: 2086153.9
A5: 应收账款 | B5: 5.5627551e+08 | C5: 6.0347318e+08 | D5: 5.1716033e+08 | E5: 4.3820437e+08 | F5: 4.1320446e+08 | G5: 3.5807201e+08
A6: 其他应收款 | B6: 69650288 | C6: 49547645 | D6: 27086472 | E6: 36082150 | F6: 41018315 | G6: 25502706
A7: 合同资产 | B7: 484618.8 | C7: 1922161.3 | D7: 2355541.8 | E7: 2363532.8
A8: 预付款项 | B8: 13981930 | C8: 21957493 | D8: 27596962 | E8: 25601542 | F8: 8383888.8 | G8: 5322052.8
A9: 应收减少 | B9: =SUM(C4:C8)-SUM(B4:B8) -> 33278483 | C9: =SUM(D4:D8)-SUM(C4:C8) -> -1.0133342e+08 | D9: =SUM(E4:E8)-SUM(D4:D8) -> -71728461 | E9: =SUM(F4:F8)-SUM(E4:E8) -> -40971031 | F9: =SUM(G4:G8)-SUM(F4:F8) -> -73964644
A11: 应付
A12: 应付票据
A13: 应付账款 | B13: 4.458657e+08 | C13: 4.5348455e+08 | D13: 3.0630474e+08 | E13: 2.1219664e+08 | F13: 1.4038947e+08 | G13: 60235681
A14: 其他应付款 | B14: 1.1666246e+08 | C14: 1.0367197e+08 | D14: 97531167 | E14: 90666378 | F14: 49333920 | G14: 35618022
A15: 合同负债 | B15: 2.1355359e+09 | C15: 1.8918741e+09 | D15: 1.7312476e+09 | E15: 1.420876e+09 | F15: 8.3275063e+08 | G15: 3.6078418e+08
A16: 应付职工薪酬 | B16: 4.8106591e+08 | C16: 4.6359106e+08 | D16: 3.9433263e+08 | E16: 3.6030722e+08 | F16: 2.4994716e+08 | G16: 1.5529453e+08
A17: 应交税费 | B17: 80085593 | C17: 70268323 | D17: 45606445 | E17: 55460575 | F17: 1.1242866e+08 | G17: 37890686
A18: 其他流动负债 | B18: 1.0721531e+08 | C18: 1.3416301e+08 | D18: 1.0935069e+08 | E18: 88406222 | F18: 52964852 | G18: 18944336
A19: 其他非流动负债 | B19: 9.433486e+08 | C19: 6.058109e+08 | D19: 3.1066637e+08 | E19: 1.6691384e+08 | F19: 84923225 | G19: 57945108
A20: 递延收益 | B20: 2392855.7 | C20: 36640187 | D20: 43847197 | E20: 66634447 | F20: 83720563 | G20: 35553471
A21: 应付增加 | B21: =SUM(B12:B20)-SUM(C12:C20) -> 5.5266818e+08 | C21: =SUM(C12:C20)-SUM(D12:D20) -> 7.206173e+08 | D21: =SUM(D12:D20)-SUM(E12:E20) -> 5.7742551e+08 | E21: =SUM(E12:E20)-SUM(F12:F20) -> 8.5500286e+08 | F21: =SUM(F12:F20)-SUM(G12:G20) -> 8.4419247e+08
A23: 存货 | B23: 977813.13 | C23: 1588564.1 | D23: 1355157 | E23: 2493895.3 | F23: 1545135.9 | G23: 1625294.3
A24: 存货减少 | B24: =C23-B23 -> 610750.98 | C24: =D23-C23 -> -233407.07 | D24: =E23-D23 -> 1138738.2 | E24: =F23-E23 -> -948759.37 | F24: =G23-F23 -> 80158.4

Sheet 收入成本
B1: 2024 | C1: 2023 | D1: 2022 | E1: 2021 | F1: 2020 | G1: 2019 | H1: 2018
A2: 收入
A3: WPS个人业务 | B3: 3.2832925e+09
A4: WPS 365业务 | B4: 4.3650005e+08
A5: WPS 软件业务 | B5: 1.2679458e+09
A6: 其他 | B6: 1.3310043e+08
A8: 国内个人办公服务订阅业务 | C8: 2.6533478e+09 | D8: 2.0501271e+09 | E8: 1.4652985e+09 | F8: 1.1088805e+09 | G8: 6.7952999e+08
A9: 国内机构订阅及服务业务 | C9: 9.5743488e+08 | D9: 691989137 | E9: 4.4626203e+08
A10: 国内机构授权业务 | C10: 6.551452e+08 | D10: 8.3562053e+08 | E10: 9.6244853e+08 | F10: 8.0277615e+08 | G10: 4.0406088e+08
A11: 互联网广告推广服务及其他业务 | C11: 2.9004044e+08 | D11: 3.0644795e+08 | E11: 4.0560205e+08 | F11: 3.490788e+08 | G11: 4.9584121e+08
A13: 成本
A14: WPS个人业务 | B14: 6.1743714e+08
A15: WPS 365业务 | B15: 38597698
A16: WPS 软件业务 | B16: 92285167
A17: 其他 | B17: 12441908
A19: 国内个人办公服务订阅业务 | C19: 4.9102611e+08 | D19: 3.9465899e+08 | E19: 2.5211766e+08 | F19: 1.6950594e+08 | G19: 1.30922e+08
A20: 国内机构订阅及服务业务 | C20: 69896550 | D20: 45732607 | E20: 22910359
A21: 国内机构授权业务 | C21: 45043823 | D21: 54917864 | E21: 38139386 | F21: 31581106 | G21: 84207292
A22: 互联网广告推广服务及其他业务 | C22: 63873653 | D22: 86963741 | E22: 1.1573906e+08 | F22: 76811386 | G22: 12541145
A24: 主营业务收入 | B24: 5.119463e+09 | C24: 4.5538495e+09 | D24: 3.8841847e+09 | E24: 3.2796111e+09 | F24: 2.2607354e+09 | G24: 1.5794321e+09 | H24: 1.1295442e+09
A25: 主营业务成本 | B25: 7.5978507e+08 | C25: 6.6878086e+08 | D25: 5.822732e+08 | E25: 4.2890647e+08 | F25: 2.7789843e+08 | G25: 2.2767043e+08 | H25: 1.4997763e+08
A26: 主营业务毛利 | B26: =B24-B25 -> 4.3596779e+09 | C26: =C24-C25 -> 3.8850687e+09 | D26: =D24-D25 -> 3.3019115e+09 | E26: =E24-E25 -> 2.8507046e+09 | F26: =F24-F25 -> 1.982837e+09 | G26: =G24-G25 -> 1.3517616e+09 | H26: =H24-H25 -> 9.795666e+08
A27: 毛利率 | B27: =B26/B24 -> 0.85158891 | C27: =C26/C24 -> 0.85313945 | D27: =D26/D24 -> 0.85009127 | E27: =E26/E24 -> 0.86922033 | F27: =F26/F24 -> 0.87707609 | G27: =G26/G24 -> 0.85585298 | H27: =H26/H24 -> 0.86722288
A28: 其他业务收入 | B28: 1375821.2 | C28: 2118764.9 | D28: 774759.28 | E28: 447652.85 | F28: 232986.85 | G28: 88531.37 | H28: 136912.34
A29: 其他业务成本 | B29: 976847.73 | C29: 1059280 | D29: 637454.61 | E29: 446317.47 | F29: 236511.47 | G29: 95300 | H29: 136250
A30: 其他业务毛利 | B30: =B28-B29 -> 398973.52 | C30: =C28-C29 -> 1059484.9 | D30: =D28-D29 -> 137304.67 | E30: =E28-E29 -> 1335.38 | F30: =F28-F29 -> -3524.62 | G30: =G28-G29 -> -6768.63 | H30: =H28-H29 -> 662.34
A31: 毛利率 | B31: =B30/B28 -> 0.28998936 | C31: =C30/C28 -> 0.50004836 | D31: =D30/D28 -> 0.17722236 | E31: =E30/E28 -> 0.0029830705 | F31: =F30/F28 -> -0.015127978 | G31: =G30/G28 -> -0.076454595 | H31: =H30/H28 -> 0.004837694

Sheet Beta_04
B1: 定价 | C1: 定价 | D1: 2024 | E1: 2023 | F1: 2022 | G1: 2021 | H1: 2020 | I1: 2019
A2: 资产 | D2: ='balance sheet（处理后）'!C2 -> 1.5912889e+10 | E2: ='balance sheet（处理后）'!D2 -> 1.3974021e+10 | F2: ='balance sheet（处理后）'!E2 -> 1.2057677e+10 | G2: ='balance sheet（处理后）'!F2 -> 1.0425669e+10 | H2: ='balance sheet（处理后）'!G2 -> 8.5115862e+09 | I2: ='balance sheet（处理后）'!H2 -> 6.8439935e+09
A3: 现金 | D3: ='balance sheet（处理后）'!C3 -> 1.2812479e+10 | E3: ='balance sheet（处理后）'!D3 -> 1.1392118e+10 | F3: ='balance sheet（处理后）'!E3 -> 1.0293767e+10 | G3: ='balance sheet（处理后）'!F3 -> 9.2193082e+09 | H3: ='balance sheet（处理后）'!G3 -> 7.6442103e+09 | I3: ='balance sheet（处理后）'!H3 -> 6.2955176e+09
A4: 投资 | D4: ='balance sheet（处理后）'!C10 -> 1.5837826e+09 | E4: ='balance sheet（处理后）'!D10 -> 1.1148938e+09 | F4: ='balance sheet（处理后）'!E10 -> 4.913314e+08 | G4: ='balance sheet（处理后）'!F10 -> 1.6841795e+08 | H4: ='balance sheet（处理后）'!G10 -> 53083238 | I4: ='balance sheet（处理后）'!H10 -> 38612671
A5: 运营资产 | D5: ='balance sheet（处理后）'!C15 -> 7.2816093e+08 | E5: ='balance sheet（处理后）'!D15 -> 7.6115434e+08 | F5: ='balance sheet（处理后）'!E15 -> 647433732 | G5: ='balance sheet（处理后）'!F15 -> 5.3505509e+08 | H5: ='balance sheet（处理后）'!G15 -> 4.961692e+08 | I5: ='balance sheet（处理后）'!H15 -> 4.1410836e+08
A6: 应收 | D6: ='balance sheet（处理后）'!C16+'balance sheet（处理后）'!C17 -> 5.0987671e+08 | E6: ='balance sheet（处理后）'!D16+'balance sheet（处理后）'!D17 -> 5.6902035e+08 | F6: ='balance sheet（处理后）'!E16+'balance sheet（处理后）'!E17 -> 5.0023927e+08 | G6: ='balance sheet（处理后）'!F16+'balance sheet（处理后）'!F17 -> 4.1519832e+08 | H6: ='balance sheet（处理后）'!G16+'balance sheet（处理后）'!G17 -> 4.0044938e+08 | I6: ='balance sheet（处理后）'!H16+'balance sheet（处理后）'!H17 -> 3.4710952e+08
A7: 预付 | D7: =balance!C18 -> 13981930 | E7: =balance!D18 -> 21957493 | F7: =balance!E18 -> 27596962 | G7: =balance!F18 -> 25601542 | H7: =balance!G18 -> 8383888.8 | I7: =balance!H18 -> 5322052.8
A8: 存货 | D8: ='balance sheet（处理后）'!C20 -> 802036.62 | E8: ='balance sheet（处理后）'!D20 -> 1412787.6 | F8: ='balance sheet（处理后）'!E20 -> 1157966.9 | G8: ='balance sheet（处理后）'!F20 -> 2296705.1 | H8: ='balance sheet（处理后）'!G20 -> 1347945.7 | I8: ='balance sheet（处理后）'!H20 -> 1428104.1
A9: 长期资产 | D9: ='balance sheet（处理后）'!C26 -> 7.8846634e+08 | E9: ='balance sheet（处理后）'!D26 -> 7.0585543e+08 | F9: ='balance sheet（处理后）'!E26 -> 6.2514484e+08 | G9: ='balance sheet（处理后）'!F26 -> 5.0288813e+08 | H9: ='balance sheet（处理后）'!G26 -> 3.1812341e+08 | I9: ='balance sheet（处理后）'!H26 -> 95754892
A10: 负债 | D10: ='balance sheet（处理后）'!C34 -> 4.4763191e+09 | E10: ='balance sheet（处理后）'!D34 -> 3.9544151e+09 | F10: ='balance sheet（处理后）'!E34 -> 3.2592856e+09 | G10: ='balance sheet（处理后）'!F34 -> 2.6454601e+09 | H10: ='balance sheet（处理后）'!G34 -> 1.6207629e+09 | I10: ='balance sheet（处理后）'!H34 -> 7.7541323e+08
A11: 预收 | D11: ='balance sheet（处理后）'!C38+'balance sheet（处理后）'!C46 -> 3.0788845e+09 | E11: ='balance sheet（处理后）'!D38+'balance sheet（处理后）'!D46 -> 2.504513e+09 | F11: ='balance sheet（处理后）'!E38+'balance sheet（处理后）'!E46 -> 2.048529e+09 | G11: ='balance sheet（处理后）'!F38+'balance sheet（处理后）'!F46 -> 1.5942159e+09 | H11: ='balance sheet（处理后）'!G38+'balance sheet（处理后）'!G46 -> 9.1767385e+08 | I11: ='balance sheet（处理后）'!H38+'balance sheet（处理后）'!H46 -> 0
A12: 应付 | D12: ='balance sheet（处理后）'!C36 -> 4.458657e+08 | E12: ='balance sheet（处理后）'!D36 -> 4.5348455e+08 | F12: ='balance sheet（处理后）'!E36 -> 3.0630474e+08 | G12: ='balance sheet（处理后）'!F36 -> 2.1219664e+08 | H12: ='balance sheet（处理后）'!G36 -> 1.4038947e+08 | I12: ='balance sheet（处理后）'!H36 -> 60235681
A13: 有息负债 | D13: ='balance sheet（处理后）'!C49+'balance sheet（处理后）'!C52 -> 1.1310118e+08 | E13: ='balance sheet（处理后）'!D49+'balance sheet（处理后）'!D52 -> 78405526 | F13: ='balance sheet（处理后）'!E49+'balance sheet（处理后）'!E52 -> 1.3526932e+08 | G13: ='balance sheet（处理后）'!F49+'balance sheet（处理后）'!F52 -> 1.145132e+08 | H13: ='balance sheet（处理后）'!G49+'balance sheet（处理后）'!G52 -> 0 | I13: ='balance sheet（处理后）'!H49+'balance sheet（处理后）'!H52 -> 0
A14: 权益 | D14: ='balance sheet（处理后）'!C55 -> 1.143657e+10 | E14: ='balance sheet（处理后）'!D55 -> 1.0019606e+10 | F14: ='balance sheet（处理后）'!E55 -> 8.798391e+09 | G14: ='balance sheet（处理后）'!F55 -> 7.7802093e+09 | H14: ='balance sheet（处理后）'!G55 -> 6.8908233e+09 | I14: ='balance sheet（处理后）'!H55 -> 6.0685803e+09
A15: 资本投入 | D15: ='balance sheet（处理后）'!C56+'balance sheet（处理后）'!C57+'balance sheet（处理后）'!C58 -> 5.8032875e+09 | E15: ='balance sheet（处理后）'!D56+'balance sheet（处理后）'!D57+'balance sheet（处理后）'!D58 -> 5.6395207e+09 | F15: ='balance sheet（处理后）'!E56+'balance sheet（处理后）'!E57+'balance sheet（处理后）'!E58 -> 5.4028629e+09 | G15: ='balance sheet（处理后）'!F56+'balance sheet（处理后）'!F57+'balance sheet（处理后）'!F58 -> 5.2085227e+09 | H15: ='balance sheet（处理后）'!G56+'balance sheet（处理后）'!G57+'balance sheet（处理后）'!G58 -> 5.1029105e+09 | I15: ='balance sheet（处理后）'!H56+'balance sheet（处理后）'!H57+'balance sheet（处理后）'!H58 -> 5.0492526e+09
A16: 未分配利润 | D16: ='balance sheet（处理后）'!C61 -> 5.3013467e+09 | E16: ='balance sheet（处理后）'!D61 -> 4.0930628e+09 | F16: ='balance sheet（处理后）'!E61 -> 3.1570626e+09 | G16: ='balance sheet（处理后）'!F61 -> 2.4081747e+09 | H16: ='balance sheet（处理后）'!G61 -> 1.6808484e+09 | I16: ='balance sheet（处理后）'!H61 -> 9.5315356e+08
A17: 股息分红 | D17: =balance!C63 -> 4.1599127e+08 | E17: =balance!D63 -> 4.0629176e+08 | F17: =balance!E63 -> 322700000 | G17: =balance!F63 -> 0 | H17: =balance!G63 -> 276600000 | I17: =balance!H63 -> 138300000
A19: 现金结构
A20: 利润留存 | D20: =D16 -> 5.3013467e+09 | E20: =E16 -> 4.0930628e+09 | F20: =F16 -> 3.1570626e+09 | G20: =G16 -> 2.4081747e+09 | H20: =H16 -> 1.6808484e+09 | I20: =I16 -> 9.5315356e+08
A21: 股东、负债 | D21: =D3-D20 -> 7.5111322e+09 | E21: =E3-E20 -> 7.2990549e+09 | F21: =F3-F20 -> 7.136704e+09 | G21: =G3-G20 -> 6.8111335e+09 | H21: =H3-H20 -> 5.9633619e+09 | I21: =I3-I20 -> 5.342364e+09
A23: 折旧摊销 | D23: =SUM(损益现金流!B29:B34) -> 1.3881981e+08 | E23: =SUM(损益现金流!C29:C34) -> 1.4778971e+08 | F23: =SUM(损益现金流!D29:D34) -> 1.5550197e+08 | G23: =SUM(损益现金流!E29:E34) -> 1.0724077e+08 | H23: =SUM(损益现金流!F29:F34) -> 51310272 | I23: =SUM(损益现金流!G29:G34) -> 39224630
A24: 资本开支 | D24: =损益现金流!B64 -> 1.7499178e+08 | E24: =损益现金流!C64 -> 1.6584838e+08 | F24: =损益现金流!D64 -> 1.7596185e+08 | G24: =损益现金流!E64 -> 1.4884581e+08 | H24: =损益现金流!F64 -> 55277441 | I24: =损益现金流!G64 -> 63210239
A26: 股本 | B26: =C26 -> 462525643 | C26: =D26 -> 462525643 | D26: ='balance sheet（处理后）'!C56 -> 462525643 | E26: ='balance sheet（处理后）'!D56 -> 461723327 | F26: ='balance sheet（处理后）'!E56 -> 461221529 | G26: ='balance sheet（处理后）'!F56 -> 461000000 | H26: ='balance sheet（处理后）'!G56 -> 461000000 | I26: ='balance sheet（处理后）'!H56 -> 461000000
A28: 主营收入 | D28: =收入成本!B24 -> 5.119463e+09 | E28: =收入成本!C24 -> 4.5538495e+09 | F28: =收入成本!D24 -> 3.8841847e+09 | G28: =收入成本!E24 -> 3.2796111e+09 | H28: =收入成本!F24 -> 2.2607354e+09 | I28: =收入成本!G24 -> 1.5794321e+09
A29: 主营成本 | D29: =收入成本!B25 -> 7.5978507e+08 | E29: =收入成本!C25 -> 6.6878086e+08 | F29: =收入成本!D25 -> 5.822732e+08 | G29: =收入成本!E25 -> 4.2890647e+08 | H29: =收入成本!F25 -> 2.7789843e+08 | I29: =收入成本!G25 -> 2.2767043e+08
A30: 费用 | D30: =SUM(损益现金流!B5:B8) -> 3.1387226e+09 | E30: =SUM(损益现金流!C5:C8) -> 2.9210997e+09 | F30: =SUM(损益现金流!D5:D8) -> 2.5760593e+09 | G30: =SUM(损益现金流!E5:E8) -> 2.1377774e+09 | H30: =SUM(损益现金流!F5:F8) -> 1.4291526e+09 | I30: =SUM(损益现金流!G5:G8) -> 1.0951569e+09
A31: 研发费用 | D31: =损益现金流!B8 -> 1.6955569e+09 | E31: =损益现金流!C8 -> 1.4722958e+09 | F31: =损益现金流!D8 -> 1.3312108e+09 | G31: =损益现金流!E8 -> 1.081625e+09 | H31: =损益现金流!F8 -> 7.1088189e+08 | I31: =损益现金流!G8 -> 5.9878566e+08
A32: 销售费用 | D32: =损益现金流!B6 -> 9.9133253e+08 | E32: =损益现金流!C6 -> 9.6741454e+08 | F32: =损益现金流!D6 -> 8.1820166e+08 | G32: =损益现金流!E6 -> 6.9497017e+08 | H32: =损益现金流!F6 -> 4.8280766e+08 | I32: =损益现金流!G6 -> 3.4473805e+08
A33: 管理费用 | D33: =损益现金流!B7 -> 4.0266289e+08 | E33: =损益现金流!C7 -> 4.4422792e+08 | F33: =损益现金流!D7 -> 3.9190309e+08 | G33: =损益现金流!E7 -> 3.2600319e+08 | H33: =损益现金流!F7 -> 2.1254109e+08 | I33: =损益现金流!G7 -> 1.356965e+08
A34: 损耗 | D34: =SUM(损益现金流!B9:B11) -> -23786292 | E34: =SUM(损益现金流!C9:C11) -> -18026045 | F34: =SUM(损益现金流!D9:D11) -> -24993544 | G34: =SUM(损益现金流!E9:E11) -> -11519371 | H34: =SUM(损益现金流!F9:F11) -> -4165620 | I34: =SUM(损益现金流!G9:G11) -> -7085348
A35: 其他收益 | D35: =损益现金流!B12 -> 1.7612308e+08 | E35: =损益现金流!C12 -> 1.42203e+08 | F35: =损益现金流!D12 -> 1.7304803e+08 | G35: =损益现金流!E12 -> 1.9860388e+08 | H35: =损益现金流!F12 -> 1.1471942e+08 | I35: =损益现金流!G12 -> 67353894
A36: 现金收益 | D36: =损益现金流!B19 -> 2.9925526e+08 | E36: =损益现金流!C19 -> 2.8773638e+08 | F36: =损益现金流!D19 -> 2.6637802e+08 | G36: =损益现金流!E19 -> 2.4223408e+08 | H36: =损益现金流!F19 -> 1.9651954e+08 | I36: =损益现金流!G19 -> 76939832
A37: 股权收益 | D37: =损益现金流!B22 -> 78723411 | E37: =损益现金流!C22 -> 33805900 | F37: =损益现金流!D22 -> 66723048 | G37: =损益现金流!E22 -> -14148541 | H37: =损益现金流!F22 -> 75669097 | I37: =损益现金流!G22 -> 8674326.6
A38: 利息支出 | D38: =损益现金流!B24 -> 0 | E38: =损益现金流!C24 -> 0 | F38: =损益现金流!D24 -> 0 | G38: =损益现金流!E24 -> 0 | H38: =损益现金流!F24 -> 0 | I38: =损益现金流!G24 -> 0
A39: 财务费用 | D39: =损益现金流!B25 -> 10620632 | E39: =损益现金流!C25 -> 10167473 | F39: =损益现金流!D25 -> 10583095 | G39: =损益现金流!E25 -> 6802562.5 | H39: =损益现金流!F25 -> 1049480.2 | I39: =损益现金流!G25 -> 833619.92
A40: 其他业务
A41: 收入 | D41: =收入成本!B28 -> 1375821.2 | E41: =收入成本!C28 -> 2118764.9 | F41: =收入成本!D28 -> 774759.28 | G41: =收入成本!E28 -> 447652.85 | H41: =收入成本!F28 -> 232986.85 | I41: =收入成本!G28 -> 88531.37
A42: 成本 | D42: =收入成本!B29 -> 976847.73 | E42: =收入成本!C29 -> 1059280 | F42: =收入成本!D29 -> 637454.61 | G42: =收入成本!E29 -> 446317.47 | H42: =收入成本!F29 -> 236511.47 | I42: =收入成本!G29 -> 95300
A43: 营业外
A44: 收入 | D44: =损益现金流!B13 -> 3918649.7 | E44: =损益现金流!C13 -> 1470784 | F44: =损益现金流!D13 -> 2197939.3 | G44: =损益现金流!E13 -> 3618260.6 | H44: =损益现金流!F13 -> 807603.11 | I44: =损益现金流!G13 -> 0
...
